Workbook
Name Cliente: 'AG-ADM-F10-00'!$B$2:$B$72
Name Contacto: 'AG-ADM-F10-00'!$D$2:$D$72
Name Correo: 'AG-ADM-F10-00'!$E$2:$E$72
Name Domicilio: 'AG-ADM-F10-00'!$C$2:$C$72
Name Nombre: 'AG-ADM-F10-00'!$A$2:$A$72
Name Nominal: Patrones!$E$5:$E$16
Name Tel: 'AG-ADM-F10-00'!$F$2:$F$72
Name Valores: Calculos!$N$13:$N$17
Name Valores1: Calculos!$M$13:$M$17
Name valores3: Calculos!$O$13:$O$17
Name Valoresss: Calculos!$M$11:$P$17

Sheet Portada
M1: JECG
D7: CERTIFICADO DE CALIBRACIÓN
I8: Hoja: 1 | J8: de 2
H9: No. De Certificado: | I9: =Calculos!E4 -> AGP-0100-26
B11: Datos del Cliente/ Client Data
B13: =Calculos!A5 -> Cliente: | C13: =Calculos!A4 -> Metrics Works Saltillo
B14: =Calculos!A6 -> Domicilio: | C14: =Calculos!B6 -> Carr. Querétaro-Tequisquiapan 22500-A, 76270 Santiago de Querétaro, Qro.
B15: =Calculos!A7 -> Contacto: | C15: =Calculos!B7 -> Ing. Wilfrido Nuñez | D15: =Calculos!D6 -> Tel: | E15: =Calculos!E6 -> (44) 2480 7334 | F15: =Calculos!D7 -> Ext: | G15: =Calculos!E7 -> N/A | H15: =Calculos!D5 -> Correo: | I15: =Calculos!E5 -> JOSEW.NUNEZ@TECHOPS.MX
B18: Datos del Instrumento/ Instrument Data
C20: =Calculos!A9 -> Instrumento: | D20: =Calculos!B9 -> 0 | H20: =Calculos!E9 -> ID: | I20: =Calculos!F9 -> 1651
C22: =Calculos!A10 -> Marca: | D22: =Calculos!B10 -> 0 | H22: =Calculos!E10 -> Alcance de Medición: | I22: =Calculos!F10 -> 0.2 | J22: =Calculos!J10 -> psi
C24: =Calculos!A11 -> 0 | D24: =Calculos!B11 -> 0 | H24: =Calculos!E11 -> Magnitud: | I24: =Calculos!F11 -> Presión
C26: =Calculos!A12 -> No de Serie: | D26: =Calculos!B12 -> 0 | H26: =Calculos!E12 -> Ubicación | I26: =Calculos!F12 -> N/A
B30: Datos Generales/General Data
C32: Fecha de Recepción: | D32: =Calculos!I4 -> Servicio en Sitio | H32: Procedimiento de Calibración: | I32: PR-AG-CAL-03-00
I33: (Procedimiento interno)
C34: Fecha de Calibración: | D34: =Calculos!I5 -> 45918 | H34: Temperatura: | I34: =AVERAGE(Calculos!J13,Calculos!F13) -> 26.1
C36: Fecha Sugerida: | D36: =Calculos!I6 -> 46283 | H36: Humedad Relativa: | I36: =AVERAGE(Calculos!F14,Calculos!J14) -> 46.5
C38: Fecha de Elaboración: | D38: =Calculos!I7 -> 45918 | H38: Lugar de Calibración: | I38: =Calculos!C14 -> Instalaciones de Cliente
C40: Trazabilidad: | D40: Vía CENAM | H40: Documento de Referencia: | I40: NOM-013-SCFI
B42: Método de calibración: | D42: Comparación directa
B43: Datos del Patrón Utilizado
B44: Patrón | D44: ID | E44: No. De Certificado | F44: Marca | G44: Modelo | H44: No. De Serie | I44: Vigencia
B46: =IF(Calculos!$F$10<=Patrones!$E$16,Calculos!M4,"") -> Manómetro Digital | D46: =IF($B$46="Manómetro Digital",Calculos!N4,"") -> AG-052 | E46: =IF($B$46="Manómetro Digital",Calculos!O4,"") -> 1-23207 | F46: =IF($B$46="Manómetro Digital",Calculos!P4,"") -> Druck | G46: =IF($B$46="Manómetro Digital",Calculos!Q4,"") -> DPI104 | H46: =IF($B$46="Manómetro Digital",Calculos!R4,"") -> 5335895 | I46: =IF($B$46="Manómetro Digital",Calculos!S4,"") -> 45989 | K46: =TODAY() -> 46070
B47: =IF(Calculos!$F$10>Patrones!$E$16,Calculos!$M$5,"") | D47: =IF(Calculos!$F$10>Patrones!$E$16,Calculos!$N$5,"") | E47: =IF(Calculos!$F$10>Patrones!$E$16,Calculos!$O$5,"") | F47: =IF(Calculos!$F$10>Patrones!$E$16,Calculos!$P$5,"") | G47: =IF(Calculos!$F$10>Patrones!$E$16,Calculos!$Q$5,"") | H47: =IF(Calculos!$F$10>Patrones!$E$16,Calculos!$R$5,"") | I47: =IF($B$47="Manómetro Digital",Calculos!S5,"")
E48: =IF(I46<TODAY(),"Patrón Vencido","") -> Patrón Vencido
A52: =Calculos!M9 -> Calibró | G52: =Calculos!O9 -> Aprobó
A55: =Calculos!M8 -> 0 | G55: =Calculos!O8 -> Viridiana Moreno
A56: Metrología | G56: Calidad
B57: * Los resultados disponibles en este documento corresponden unicamente al instrumento descrito y encontrado al momento de la calibración.
B58: *Los resultados expresados en este certificado corresponden al promedio de una serie de mediciones.
B59: * Los patrones utilizados cuentan con trazabilidad a los patrones nacionales mantenidos por CENAM/NIST u otra Organización equivalente.
B60: * Los resultados de medición son trazables al Sistema Internacional de Unidades (SI).
B61: * La incertidumbre calculada es de acuerdo a la GUM para la expresión de incertidumbre de medición, con un nivel de confianza del 95% con un factor de cobertura de k=2.
B62: (Guide to the Expression of Uncertainty in Measurement-1995)
B63: * La reproducción de éste certificado solo puede ser en forma total y con autorización previa del laboratorio.
B64: *Es responsabilidad del usuario establecer la fecha de una nueva calibración.
B65: *El tiempo de validez de los resultados depende tanto de las caracteristicas del instrumento como de las practicas de uso y manejo.
A70: AG-CER-CAL-C01-01 | C70: =Resultados!D76 -> Este certificado no puede ser modificado en forma total o parcial sin la autorización previa de Equipos y Servicios Especializados AG, S.A. de C.V. y solo tiene válidez en su presentación original.
A72: <

Sheet Resultados
M4: HIGHWAY TRUCKS SAPI DE CV
I8: Hoja: 2 | J8: de 2
H10: =Portada!H9 -> No. De Certificado: | J10: =Portada!I9 -> AGP-0100-26
A12: RESULTADOS DE LA CALIBRACIÓN
A19: Inspección inicial
E20: Patrón | F20: Instrumento | G20: Error | H20: Resultado
E21: =D33 -> psi | F21: =E21 -> psi | G21: =F21 -> psi
E22: =Calculos!I20 -> 0.04 | F22: =Calculos!H20 -> 0.04 | G22: =Calculos!J20 -> 0 | H22: =Calculos!K20 -> ACEPTADO
E23: =Calculos!I21 -> 0.1 | F23: =Calculos!H21 -> 0.1 | G23: =Calculos!J21 -> 0 | H23: =Calculos!K21 -> ACEPTADO
E24: =Calculos!I22 -> 0.2 | F24: =Calculos!H22 -> 0.2 | G24: =Calculos!J22 -> 0 | H24: =Calculos!K22 -> ACEPTADO
D32: Patrón | E32: Instrumento | F32: Error Instrumental | G32: Incertidumbre Expandida (±) | H32: *EMP (±) | I32: **Resultado
D33: =Calculos!J10 -> psi | E33: =D33 -> psi | F33: =E33 -> psi | G33: =F33 -> psi | H33: =G33 -> psi
D34: =Calculos!O28 -> 0.048 | E34: =Calculos!N28 -> 0.05 | F34: =Calculos!P28 -> 0.002 | G34: =Calculos!AE28 -> 0.1292504 | H34: =Calculos!Q28 -> 0.01 | I34: =Calculos!S28 -> RECHAZADO | L34: =ABS(F34)+G34 -> 0.1312504
D35: =Calculos!O29 -> 0.099 | E35: =Calculos!N29 -> 0.1 | F35: =Calculos!P29 -> 0.001 | G35: =Calculos!AE29 -> 0.1292504 | H35: =Calculos!Q29 -> 0.01 | I35: =Calculos!S29 -> RECHAZADO | L35: =ABS(F35)+G35 -> 0.1302504
D36: =Calculos!O30 -> 0.149 | E36: =Calculos!N30 -> 0.15 | F36: =Calculos!P30 -> 0.001 | G36: =Calculos!AE30 -> 0.1292504 | H36: =Calculos!Q30 -> 0.01 | I36: =Calculos!S30 -> RECHAZADO | L36: =ABS(F36)+G36 -> 0.1302504
D37: =Calculos!O31 | E37: =Calculos!N31 | F37: =Calculos!P31 | G37: =Calculos!AE31 -> #DIV/0! | H37: =Calculos!Q31 -> 0.01 | I37: =Calculos!S31 | L37: =ABS(F37)+G37 -> #VALUE!
D38: =Calculos!O32 | E38: =Calculos!N32 | F38: =Calculos!P32 | G38: =Calculos!AE32 -> #DIV/0! | H38: =Calculos!Q32 -> 0.01 | I38: =Calculos!S32 | L38: =ABS(F38)+G38 -> #VALUE!
D39: =Calculos!O33 | E39: =Calculos!N33 | F39: =Calculos!P33 | G39: =Calculos!AE33 -> #DIV/0! | H39: =Calculos!Q33 -> 0.01 | I39: =Calculos!S33 | L39: =ABS(F39)+G39 -> #VALUE!
D40: =Calculos!O34 | E40: =Calculos!N34 | F40: =Calculos!P34 | G40: =Calculos!AE34 -> #DIV/0! | H40: =Calculos!Q34 -> 0.01 | I40: =Calculos!S34 | L40: =ABS(F40)+G40 -> #VALUE!
D41: =Calculos!O35 | E41: =Calculos!N35 | F41: =Calculos!P35 | G41: =Calculos!AE35 -> #DIV/0! | H41: =Calculos!Q35 -> 0.01 | I41: =Calculos!S35 | L41: =ABS(F41)+G41 -> #VALUE!
C42: 9 | D42: =Calculos!O36 | E42: =Calculos!N36 | F42: =Calculos!P36 | G42: =Calculos!AE36 -> #DIV/0! | H42: =Calculos!Q36 -> 0.01 | I42: =Calculos!S36 | L42: =ABS(F42)+G42 -> #VALUE!
C43: 10 | D43: =Calculos!O37 | E43: =Calculos!N37 | F43: =Calculos!P37 | G43: =Calculos!AE37 -> #DIV/0! | H43: =Calculos!Q37 -> 0.01 | I43: =Calculos!S37 | L43: =ABS(F43)+G43 -> #VALUE!
I46: =COUNTIF(I34:I43,"RECHAZADO") -> 3
A48: Nota: El instrumento ha sido calibrado y es apto para su uso.
A63: *EMP: Error Máximo Permisible.
A64: **En caso de que el instrumento presente lecturas superiores al Error Máximo Permisible se reportará como 'RECHAZADO' en columna de 'Resultado'.
A65: La columna de "Resultado" representa la suma del error instrumental ± la incertidumbre expandida.
A68: Dictamen: | D68: El instrumento | E68: =IF(I46>0,"NO CUMPLE",IF(I46=0,"CUMPLE","")) -> NO CUMPLE | H68: con las especificaciones de | J68: =Calculos!F15 -> 0
A74: Fin del certificado.
A76: =Portada!A70 -> AG-CER-CAL-C01-01 | D76: Este certificado no puede ser modificado en forma total o parcial sin la autorización previa de Equipos y Servicios Especializados AG, S.A. de C.V. y solo tiene válidez en su presentación original.

Sheet Calculos
A1: Hoja de Calculos | M1: Patrones
M3: Patrón | N3: ID | O3: # Certificado | P3: Marca | Q3: Modelo | R3: Serie | S3: Vigencia
A4: =VLOOKUP(B5,'AG-ADM-F10-00'!A2:C72,2,TRUE) -> Metrics Works Saltillo | C4: ****No de Certificado: | E4: AGP-0100-26 | H4: Fecha de Recepción: | I4: Servicio en Sitio | K4: CLIENTE | M4: =Patrones!B20 -> Manómetro Digital | N4: =Patrones!D20 -> AG-052 | O4: =Patrones!D21 -> 1-23207 | P4: =Patrones!B21 -> Druck | Q4: =Patrones!B22 -> DPI104 | R4: =Patrones!B23 -> 5335895 | S4: =Patrones!D23 -> 45989
A5: Cliente: | B5: MEXICO MRO MANAGEMENT S. DE R.L. DE C.V. | D5: Correo: | E5: =VLOOKUP(B5, BD_Clientes!A:H, 4, FALSE) -> JOSEW.NUNEZ@TECHOPS.MX | H5: Fecha de Calibración: | I5: 45918 | K5: NORMA | M5: =Patrones!B4 -> Manómetro Digital | N5: =Patrones!D4 -> AG-008 | O5: =Patrones!D5 -> 1-24842 | P5: =Patrones!B5 -> Omega | Q5: =Patrones!B6 -> DPG-4000-10K | R5: =Patrones!B7 -> 9941257 | S5: =Patrones!D7 -> 46057
A6: Domicilio: | B6: =VLOOKUP(B5, BD_Clientes!A:H, 2, FALSE) -> Carr. Querétaro-Tequisquiapan 22500-A, 76270 Santiago de Querétaro, Qro. | D6: Tel: | E6: =VLOOKUP(B5, BD_Clientes!A:H, 5, FALSE) -> (44) 2480 7334 | H6: Fecha sugerida: | I6: 46283 | K6: FABRICANTE
A7: Contacto: | B7: =VLOOKUP(B5, BD_Clientes!A:H, 3, FALSE) -> Ing. Wilfrido Nuñez | D7: Ext: | E7: =VLOOKUP(B5,'AG-ADM-F10-00'!A2:G72,7,TRUE) -> N/A | H7: Fecha de Elaboración: | I7: 45918 | K7: No. De Parte:
K8: Modelo: | O8: Viridiana Moreno
A9: Instrumento: | E9: ID: | F9: 1651 | H9: División minima: | J9: 0.01 | M9: Calibró | O9: Aprobó
A10: Marca: | E10: Alcance de Medición: | F10: 0.2 | H10: Unidad: | J10: psi | K10: -8 Valores para clases de exactitud .2; .25; .4; .5; .6
E11: Magnitud: | F11: Presión | H11: Clase de Exactitud: | J11: =$J$9/$F$10*100 -> 5 | K11: -5 Valores para clases de exactitud 1; 1.6; 2; 2.5
A12: No de Serie: | E12: Ubicación | F12: N/A | H12: Resolución: | J12: =IF(B13=1,J9/2,J9) -> 0.005 | K12: -3 Valores para clases de exactitud 4 y 5
A13: TIPO: | B13: 1 | E13: Temperatura I °C: | F13: 25.1 | H13: Temperatura F °C: | J13: 27.1
A14: Lugar donde se calibró: | C14: Instalaciones de Cliente | D14: Humedad Relativa I %: | F14: 46 | H14: Humedad Relativa F %: | J14: 47
A15: *****************EMP de acuerdo a:
A16: Inspección Inicial
A18: Lecturas del Instrumento | F18: Lecturas del Patrón | H18: Reglas de decision
A19: Carga Aprox. | B19: V. Deseado | C19: X1Ascendente(+) | D19: X1Descendente(-) | F19: X1 A (+) | G19: X1 D (-) | H19: Promedio del IBC | I19: Promedio del Patrón | J19: Error Absoluto | K19: Dictamen
A20: 0.2 | C20: =F10*0.2 -> 0.04 | D20: =F10*0.2 -> 0.04 | F20: =F10*0.2 -> 0.04 | G20: =F10*0.2 -> 0.04 | H20: =AVERAGE(C20:D20) -> 0.04 | I20: =AVERAGE(F20:G20) -> 0.04 | J20: =H20-I20 -> 0 | K20: =IF(ABS(J20)>Q30,"RECHAZADO","ACEPTADO") -> ACEPTADO
A21: 0.5 | C21: =F10*0.5 -> 0.1 | D21: =F10*0.5 -> 0.1 | F21: =F10*0.5 -> 0.1 | G21: =F10*0.5 -> 0.1 | H21: =AVERAGE(C21:D21) -> 0.1 | I21: =AVERAGE(F21:G21) -> 0.1 | J21: =H21-I21 -> 0 | K21: =IF(ABS(J21)>Q31,"RECHAZADO","ACEPTADO") -> ACEPTADO
A22: 1 | B22: =F10 -> 0.2 | C22: =F10*1 -> 0.2 | D22: =F10*1 -> 0.2 | F22: =F10*1 -> 0.2 | G22: =F10*1 -> 0.2 | H22: =AVERAGE(C22:D22) -> 0.2 | I22: =AVERAGE(F22:G22) -> 0.2 | J22: =H22-I22 -> 0 | K22: =IF(ABS(J22)>Q32,"RECHAZADO","ACEPTADO") -> ACEPTADO
A24: Lecturas del Instrumento | H24: Lecturas del Patrón | N24: Cálculos de incertidumbre
N25: Promedio | O25: Promedio | P25: Error Absoluto de medición | Q25: EMP | R25: errVsEMP | S25: err+UE vs EMP | T25: desv | U25: u | V25: u | W25: u | X25: u | Y25: u | Z25: u | AA25: u | AB25: u | AC25: u | AD25: u | AE25: U
A26: V. Deseado | B26: V. Generado | C26: X1Ascendente(+) | D26: X1Descendente(-) | E26: X2Ascendente(+) | F26: X2Descendente(-) | H26: X1 Ascendente (+) | I26: X1 Descendente (-) | J26: X2 Ascendente (+) | K26: X2 Descendente (-) | N26: IBC | O26: Patrón | T26: est | U26: rep | V26: patK2 | W26: patK1 | X26: resoIBC | Y26: errPatK2 | Z26: errPatK1 | AA26: HistK2 | AB26: HistK1 | AC26: tipo B | AD26: comb | AE26: E
A27: =J10 -> psi | B27: =A27 -> psi | C27: =B27 -> psi | D27: =C27 -> psi | E27: =D27 -> psi | F27: =E27 -> psi | H27: =F27 -> psi | I27: =H27 -> psi | J27: =I27 -> psi | K27: =J27 -> psi | N27: =K27 -> psi | O27: =N27 -> psi | P27: =N27 -> psi | Q27: =P27 -> psi | R27: x | S27: x | T27: =Q27 -> psi | U27: =T27 -> psi | V27: =U27 -> psi | W27: =V27 -> psi | X27: =W27 -> psi | Y27: psi | Z27: =Y27 -> psi | AA27: =Z27 -> psi | AB27: =AA27 -> psi | AC27: =Z27 -> psi | AD27: =AC27 -> psi | AE27: =AD27 -> psi
A28: 0.05 | B28: 0.05 | C28: 0.05 | D28: 0.05 | E28: 0.05 | F28: 0.05 | H28: 0.048 | I28: 0.048 | J28: 0.048 | K28: 0.048 | M28: =AVERAGE((C29:F29)) -> 0.1 | N28: =IF(C28=0,"",AVERAGE(C28:F28)) -> 0.05 | O28: =IF(H28=0,"",AVERAGE(H28:K28)) -> 0.048 | P28: =IF(N28="","",(N28)-O28) -> 0.002 | Q28: =J9 -> 0.01 | R28: =IF(ABS(P28)>Q28,"RECHAZADO","ACEPTADO") -> ACEPTADO | S28: =IF(P28="","",IF(ABS(P28)+(AE28)>Q28,"RECHAZADO","ACEPTADO")) -> RECHAZADO | T28: =STDEV(H28:K28) -> 0 | U28: =T28/SQRT(4) -> 0 | V28: =IF(O28<Patrones!$E$7,Patrones!$G$6,VLOOKUP(Calculos!O28,Patrones!$E$6:$H$26,3,TRUE)) -> 0.058 | W28: =V28/2 -> 0.029 | X28: =$J$12/SQRT(12) -> 0.0014433757 | Y28: =IF(O28<Patrones!$E$7,Patrones!$F$6,VLOOKUP(Calculos!O28,Patrones!$E$6:$H$26,2,TRUE)) -> 0.1 | Z28: =Y28/SQRT(3) -> 0.057735027 | AA28: =ABS(W45-Y45) -> 0 | AB28: =AA28/SQRT(12) -> 0 | AC28: =SQRT(W28^2+X28^2+Z28^2) -> 0.064625201 | AD28: =SQRT(U28^2+AC28^2+AB28^2) -> 0.064625201 | AE28: =AD28*2 -> 0.1292504
A29: 0.1 | B29: 0.1 | C29: 0.1 | D29: 0.1 | E29: 0.1 | F29: 0.1 | H29: 0.099 | I29: 0.099 | J29: 0.099 | K29: 0.099 | L29: < | N29: =IF(C29=0,"",AVERAGE(C29:F29)) -> 0.1 | O29: =IF(H29=0,"",AVERAGE(H29:K29)) -> 0.099 | P29: =IF(N29="","",(N29)-O29) -> 0.001 | Q29: =Q28 -> 0.01 | R29: =IF(ABS(P29)>Q29,"RECHAZADO","ACEPTADO") -> ACEPTADO | S29: =IF(P29="","",IF(ABS(P29)+(AE29)>Q29,"RECHAZADO","ACEPTADO")) -> RECHAZADO | T29: =STDEV(H29:K29) -> 0 | U29: =T29/SQRT(4) -> 0 | V29: =IF(O29<Patrones!$E$7,Patrones!$G$6,VLOOKUP(Calculos!O29,Patrones!$E$6:$H$26,3,TRUE)) -> 0.058 | W29: =V29/2 -> 0.029 | X29: =$J$12/SQRT(12) -> 0.0014433757 | Y29: =IF(O29<Patrones!$E$7,Patrones!$F$6,VLOOKUP(Calculos!O29,Patrones!$E$6:$H$26,2,TRUE)) -> 0.1 | Z29: =Y29/SQRT(3) -> 0.057735027 | AA29: =ABS(W46-Y46) -> 0 | AB29: =AA29/SQRT(12) -> 0 | AC29: =SQRT(W29^2+X29^2+Z29^2) -> 0.064625201 | AD29: =SQRT(U29^2+AC29^2+AB29^2) -> 0.064625201 | AE29: =AD29*2 -> 0.1292504
A30: 0.15 | B30: 0.15 | C30: 0.15 | D30: 0.15 | E30: 0.15 | F30: 0.15 | H30: 0.149 | I30: 0.149 | J30: 0.149 | K30: 0.149 | N30: =IF(C30=0,"",AVERAGE(C30:F30)) -> 0.15 | O30: =IF(H30=0,"",AVERAGE(H30:K30)) -> 0.149 | P30: =IF(N30="","",(N30)-O30) -> 0.001 | Q30: =Q29 -> 0.01 | R30: =IF(ABS(P30)>Q30,"RECHAZADO","ACEPTADO") -> ACEPTADO | S30: =IF(P30="","",IF(ABS(P30)+(AE30)>Q30,"RECHAZADO","ACEPTADO")) -> RECHAZADO | T30: =STDEV(H30:K30) -> 0 | U30: =T30/SQRT(4) -> 0 | V30: =IF(O30<Patrones!$E$7,Patrones!$G$6,VLOOKUP(Calculos!O30,Patrones!$E$6:$H$26,3,TRUE)) -> 0.058 | W30: =V30/2 -> 0.029 | X30: =$J$12/SQRT(12) -> 0.0014433757 | Y30: =IF(O30<Patrones!$E$7,Patrones!$F$6,VLOOKUP(Calculos!O30,Patrones!$E$6:$H$26,2,TRUE)) -> 0.1 | Z30: =Y30/SQRT(3) -> 0.057735027 | AA30: =ABS(W47-Y47) -> 0 | AB30: =AA30/SQRT(12) -> 0 | AC30: =SQRT(W30^2+X30^2+Z30^2) -> 0.064625201 | AD30: =SQRT(U30^2+AC30^2+AB30^2) -> 0.064625201 | AE30: =AD30*2 -> 0.1292504
N31: =IF(C31=0,"",AVERAGE(C31:F31)) | O31: =IF(H31=0,"",AVERAGE(H31:K31)) | P31: =IF(N31="","",(N31)-O31) | Q31: =Q30 -> 0.01 | R31: =IF(ABS(P31)>Q31,"RECHAZADO","ACEPTADO") -> #VALUE! | S31: =IF(P31="","",IF(ABS(P31)+(AE31)>Q31,"RECHAZADO","ACEPTADO")) | T31: =STDEV(H31:K31) -> #DIV/0! | U31: =T31/SQRT(4) -> #DIV/0! | V31: =IF(O31<Patrones!$E$7,Patrones!$G$6,VLOOKUP(Calculos!O31,Patrones!$E$6:$H$26,3,TRUE)) -> #N/A | W31: =V31/2 -> #N/A | X31: =$J$12/SQRT(12) -> 0.0014433757 | Y31: =IF(O31<Patrones!$E$7,Patrones!$F$6,VLOOKUP(Calculos!O31,Patrones!$E$6:$H$26,2,TRUE)) -> #N/A | Z31: =Y31/SQRT(3) -> #N/A | AA31: =ABS(W48-Y48) -> #DIV/0! | AB31: =AA31/SQRT(12) -> #DIV/0! | AC31: =SQRT(W31^2+X31^2+Z31^2) -> #N/A | AD31: =SQRT(U31^2+AC31^2+AB31^2) -> #DIV/0! | AE31: =AD31*2 -> #DIV/0!
N32: =IF(C32=0,"",AVERAGE(C32:F32)) | O32: =IF(H32=0,"",AVERAGE(H32:K32)) | P32: =IF(N32="","",(N32)-O32) | Q32: =Q31 -> 0.01 | R32: =IF(ABS(P32)>Q32,"RECHAZADO","ACEPTADO") -> #VALUE! | S32: =IF(P32="","",IF(ABS(P32)+(AE32)>Q32,"RECHAZADO","ACEPTADO")) | T32: =STDEV(H32:K32) -> #DIV/0! | U32: =T32/SQRT(4) -> #DIV/0! | V32: =IF(O32<Patrones!$E$7,Patrones!$G$6,VLOOKUP(Calculos!O32,Patrones!$E$6:$H$26,3,TRUE)) -> #N/A | W32: =V32/2 -> #N/A | X32: =$J$12/SQRT(12) -> 0.0014433757 | Y32: =IF(O32<Patrones!$E$7,Patrones!$F$6,VLOOKUP(Calculos!O32,Patrones!$E$6:$H$26,2,TRUE)) -> #N/A | Z32: =Y32/SQRT(3) -> #N/A | AA32: =ABS(W49-Y49) -> #DIV/0! | AB32: =AA32/SQRT(12) -> #DIV/0! | AC32: =SQRT(W32^2+X32^2+Z32^2) -> #N/A | AD32: =SQRT(U32^2+AC32^2+AB32^2) -> #DIV/0! | AE32: =AD32*2 -> #DIV/0!
N33: =IF(C33=0,"",AVERAGE(C33:F33)) | O33: =IF(H33=0,"",AVERAGE(H33:K33)) | P33: =IF(N33="","",(N33)-O33) | Q33: =Q32 -> 0.01 | R33: =IF(ABS(P33)>Q33,"RECHAZADO","ACEPTADO") -> #VALUE! | S33: =IF(P33="","",IF(ABS(P33)+(AE33)>Q33,"RECHAZADO","ACEPTADO")) | T33: =STDEV(H33:K33) -> #DIV/0! | U33: =T33/SQRT(4) -> #DIV/0! | V33: =IF(O33<Patrones!$E$7,Patrones!$G$6,VLOOKUP(Calculos!O33,Patrones!$E$6:$H$26,3,TRUE)) -> #N/A | W33: =V33/2 -> #N/A | X33: =$J$12/SQRT(12) -> 0.0014433757 | Y33: =IF(O33<Patrones!$E$7,Patrones!$F$6,VLOOKUP(Calculos!O33,Patrones!$E$6:$H$26,2,TRUE)) -> #N/A | Z33: =Y33/SQRT(3) -> #N/A | AA33: =ABS(W50-Y50) -> #DIV/0! | AB33: =AA33/SQRT(12) -> #DIV/0! | AC33: =SQRT(W33^2+X33^2+Z33^2) -> #N/A | AD33: =SQRT(U33^2+AC33^2+AB33^2) -> #DIV/0! | AE33: =AD33*2 -> #DIV/0!
N34: =IF(C34=0,"",AVERAGE(C34:F34)) | O34: =IF(H34=0,"",AVERAGE(H34:K34)) | P34: =IF(N34="","",(N34)-O34) | Q34: =Q33 -> 0.01 | R34: =IF(ABS(P34)>Q34,"RECHAZADO","ACEPTADO") -> #VALUE! | S34: =IF(P34="","",IF(ABS(P34)+(AE34)>Q34,"RECHAZADO","ACEPTADO")) | T34: =STDEV(H34:K34) -> #DIV/0! | U34: =T34/SQRT(4) -> #DIV/0! | V34: =IF(O34<Patrones!$E$7,Patrones!$G$6,VLOOKUP(Calculos!O34,Patrones!$E$6:$H$26,3,TRUE)) -> #N/A | W34: =V34/2 -> #N/A | X34: =$J$12/SQRT(12) -> 0.0014433757 | Y34: =IF(O34<Patrones!$E$7,Patrones!$F$6,VLOOKUP(Calculos!O34,Patrones!$E$6:$H$26,2,TRUE)) -> #N/A | Z34: =Y34/SQRT(3) -> #N/A | AA34: =ABS(W51-Y51) -> #DIV/0! | AB34: =AA34/SQRT(12) -> #DIV/0! | AC34: =SQRT(W34^2+X34^2+Z34^2) -> #N/A | AD34: =SQRT(U34^2+AC34^2+AB34^2) -> #DIV/0! | AE34: =AD34*2 -> #DIV/0!
N35: =IF(C35=0,"",AVERAGE(C35:F35)) | O35: =IF(H35=0,"",AVERAGE(H35:K35)) | P35: =IF(N35="","",(N35)-O35) | Q35: =Q34 -> 0.01 | R35: =IF(ABS(P35)>Q35,"RECHAZADO","ACEPTADO") -> #VALUE! | S35: =IF(P35="","",IF(ABS(P35)+(AE35)>Q35,"RECHAZADO","ACEPTADO")) | T35: =STDEV(H35:K35) -> #DIV/0! | U35: =T35/SQRT(4) -> #DIV/0! | V35: =IF(O35<Patrones!$E$7,Patrones!$G$6,VLOOKUP(Calculos!O35,Patrones!$E$6:$H$26,3,TRUE)) -> #N/A | W35: =V35/2 -> #N/A | X35: =$J$12/SQRT(12) -> 0.0014433757 | Y35: =IF(O35<Patrones!$E$7,Patrones!$F$6,VLOOKUP(Calculos!O35,Patrones!$E$6:$H$26,2,TRUE)) -> #N/A | Z35: =Y35/SQRT(3) -> #N/A | AA35: =ABS(W52-Y52) -> #DIV/0! | AB35: =AA35/SQRT(12) -> #DIV/0! | AC35: =SQRT(W35^2+X35^2+Z35^2) -> #N/A | AD35: =SQRT(U35^2+AC35^2+AB35^2) -> #DIV/0! | AE35: =AD35*2 -> #DIV/0!
N36: =IF(C36=0,"",AVERAGE(C36:F36)) | O36: =IF(H36=0,"",AVERAGE(H36:K36)) | P36: =IF(N36="","",(N36)-O36) | Q36: =Q35 -> 0.01 | R36: =IF(ABS(P36)>Q36,"RECHAZADO","ACEPTADO") -> #VALUE! | S36: =IF(P36="","",IF(ABS(P36)+(AE36)>Q36,"RECHAZADO","ACEPTADO")) | T36: =STDEV(H36:K36) -> #DIV/0! | U36: =T36/SQRT(4) -> #DIV/0! | V36: =IF(O36<Patrones!$E$7,Patrones!$G$6,VLOOKUP(Calculos!O36,Patrones!$E$6:$H$26,3,TRUE)) -> #N/A | W36: =V36/2 -> #N/A | X36: =$J$12/SQRT(12) -> 0.0014433757 | Y36: =IF(O36<Patrones!$E$7,Patrones!$F$6,VLOOKUP(Calculos!O36,Patrones!$E$6:$H$26,2,TRUE)) -> #N/A | Z36: =Y36/SQRT(3) -> #N/A | AA36: =ABS(W53-Y53) -> #DIV/0! | AB36: =AA36/SQRT(12) -> #DIV/0! | AC36: =SQRT(W36^2+X36^2+Z36^2) -> #N/A | AD36: =SQRT(U36^2+AC36^2+AB36^2) -> #DIV/0! | AE36: =AD36*2 -> #DIV/0!
N37: =IF(C37=0,"",AVERAGE(C37:F37)) | O37: =IF(H37=0,"",AVERAGE(H37:K37)) | P37: =IF(N37="","",(N37)-O37) | Q37: =Q36 -> 0.01 | R37: =IF(ABS(P37)>Q37,"RECHAZADO","ACEPTADO") -> #VALUE! | S37: =IF(P37="","",IF(ABS(P37)+(AE37)>Q37,"RECHAZADO","ACEPTADO")) | T37: =STDEV(H37:K37) -> #DIV/0! | U37: =T37/SQRT(4) -> #DIV/0! | V37: =IF(O37<Patrones!$E$7,Patrones!$G$6,VLOOKUP(Calculos!O37,Patrones!$E$6:$H$26,3,TRUE)) -> #N/A | W37: =V37/2 -> #N/A | X37: =$J$12/SQRT(12) -> 0.0014433757 | Y37: =IF(O37<Patrones!$E$7,Patrones!$F$6,VLOOKUP(Calculos!O37,Patrones!$E$6:$H$26,2,TRUE)) -> #N/A | Z37: =Y37/SQRT(3) -> #N/A | AA37: =ABS(W54-Y54) -> #DIV/0! | AB37: =AA37/SQRT(12) -> #DIV/0! | AC37: =SQRT(W37^2+X37^2+Z37^2) -> #N/A | AD37: =SQRT(U37^2+AC37^2+AB37^2) -> #DIV/0! | AE37: =AD37*2 -> #DIV/0!
N38: =IF(C38=0,"",AVERAGE(C38:F38)) | O38: =IF(H38=0,"",AVERAGE(H38:K38)) | P38: =IF(N38="","",(N38)-O38) | Q38: =Q37 -> 0.01 | R38: =IF(ABS(P38)>Q38,"RECHAZADO","ACEPTADO") -> #VALUE! | S38: =IF(P38="","",IF(ABS(P38)+(AE38)>Q38,"RECHAZADO","ACEPTADO")) | T38: =STDEV(H38:K38) -> #DIV/0! | U38: =T38/SQRT(4) -> #DIV/0! | V38: =IF(O38<Patrones!$E$7,Patrones!$G$6,VLOOKUP(Calculos!O38,Patrones!$E$6:$H$26,3,TRUE)) -> #N/A | W38: =V38/2 -> #N/A | X38: =$J$12/SQRT(12) -> 0.0014433757 | Y38: =IF(O38<Patrones!$E$7,Patrones!$F$6,VLOOKUP(Calculos!O38,Patrones!$E$6:$H$26,2,TRUE)) -> #N/A | Z38: =Y38/SQRT(3) -> #N/A | AA38: =ABS(W55-Y55) -> 0 | AB38: =AA38/SQRT(12) -> 0 | AC38: =SQRT(W38^2+X38^2+Z38^2) -> #N/A | AD38: =SQRT(U38^2+AC38^2+AB38^2) -> #DIV/0! | AE38: =AD38*2 -> #DIV/0!
V45: Ascendente | W45: =AVERAGE(H28,J28) -> 0.048 | X45: Descendente | Y45: =AVERAGE(I28,K28) -> 0.048
W46: =AVERAGE(H29,J29) -> 0.099 | Y46: =AVERAGE(I29,K29) -> 0.099
W47: =AVERAGE(H30,J30) -> 0.149 | Y47: =AVERAGE(I30,K30) -> 0.149
W48: =AVERAGE(H31,J31) -> #DIV/0! | Y48: =AVERAGE(I31,K31) -> #DIV/0!
W49: =AVERAGE(H32,J32) -> #DIV/0! | Y49: =AVERAGE(I32,K32) -> #DIV/0!
...

Sheet Patrones
A1: Patrón
A4: Instrumento: | B4: Manómetro Digital | C4: ID: | D4: AG-008 | E4: Resultados en psi
A5: Marca: | B5: Omega | C5: No. Certif: | D5: 1-24842 | E5: Nominal | F5: Patrón | G5: Incertidumbre± | H5: EMP±
A6: Modelo: | B6: DPG-4000-10K | C6: Fecha Cal: | D6: 45692 | E6: 100 | F6: 0.1 | G6: 0.058 | H6: 0.375
A7: No. De Serie: | B7: 9941257 | C7: Vigencia: | D7: =D6+365 -> 46057 | E7: 200 | F7: 0.1 | G7: 0.058 | H7: 0.375
A8: Intérvalo alcance: | B8: 10000 psi | E8: 300 | F8: 0.2 | G8: 0.059 | H8: 0.375
E9: 400 | F9: 0.2 | G9: 0.059 | H9: 0.375
E10: 500 | F10: 0.3 | G10: 0.06 | H10: 0.375
E11: 600 | F11: 0.4 | G11: 0.09 | H11: 0.375
E12: 700 | F12: 0.4 | G12: 0.063 | H12: 5
E13: 800 | F13: 0.5 | G13: 0.065 | H13: 0.375
E14: 900 | F14: 0.5 | G14: 0.073 | H14: 0.375
E15: 1000 | F15: 0.6 | G15: 0.081 | H15: 0.375
E16: 1000 | F16: 1 | G16: 0.87 | H16: 5
A17: Patrón | E17: 2000 | F17: 0 | G17: 0.87 | H17: 5
E18: 3000 | F18: 0 | G18: 0.82 | H18: 5
E19: 4000 | F19: 0 | G19: 0.83 | H19: 5
A20: Instrumento: | B20: Manómetro Digital | C20: ID: | D20: AG-052 | E20: 5000 | F20: 2 | G20: 0.61 | H20: 5
A21: Marca: | B21: Druck | C21: No. Certif: | D21: 1-23207 | E21: 6000 | F21: 2 | G21: 0.9 | H21: 5
A22: Modelo: | B22: DPI104 | C22: Fecha Cal: | D22: 45624 | E22: 7000 | F22: 2 | G22: 0.86 | H22: 5
A23: No. De Serie: | B23: 5335895 | C23: Vigencia: | D23: =D22+365 -> 45989 | E23: 8000 | F23: 1 | G23: 0.92 | H23: 5
A24: Intérvalo alcance: | B24: 750 psi | E24: 9000 | F24: 1 | G24: 0.89 | H24: 5
E25: 10000 | F25: 3 | G25: 0.69 | H25: 5
I40: |
A45: Conversiones
A49: psi | B49: Pa | C49: Mpa | D49: kPa | E49: Hpa | F49: inHg | G49: bar | H49: mbar | I49: inH2O 20 °C
A50: =B50*0.0001450377 -> -14.50377 | B50: -100000 | C50: =B50*0.0001 -> -10 | D50: =B50*0.001 -> -100 | E50: =B50/100 -> -1000
A51: =B51*0.0001450377 -> 0.0001450377 | B51: 1 | C51: =B51*0.0001 -> 0.0001 | D51: =B51*0.001 -> 0.001 | E51: =B51/100 -> 0.01
A52: =B52*0.0001450377 -> 145.0377 | B52: 1000000
A53: =B53*0.0001450377 -> 1450.377 | B53: 10000000
A54: =B54*0.0001450377 -> 1.450377 | B54: 10000

Sheet CMC
A1: Presupuesto de incertidumbre de la medición | D1: Intervalo o tamaño nominal: | G1: =Calculos!F10 -> 0.2 | H1: =Calculos!J10 -> psi | I1: Capacidad de Medición y Calibración (CMC): | K1: =J19 -> 0.12934708
A2: Campo de calibración: | B2: Presión | F2: Instrumento(s): patrón: | H2: =Portada!B46 -> Manómetro Digital | J2: =Portada!D46 -> AG-052
A3: Instrumento, Cantidad o Indicador: | B3: =Calculos!B9 -> 0 | H3: =Portada!B47 | J3: =Portada!D47
A4: Condiciones Ambientales: | B4: =Portada!I34 -> 26.1 | D4: =Portada!I36 -> 46.5
A5: Magnitud | D5: Incertidumbre | I5: Coeficientes de Sensibildad | J5: Contribución | K5: Incertidumbre Asociada
A6: Fuente de contribución | B6: Valor | C6: Unidad en | D6: Tipo | E6: Fuente | F6: Distribución | G6: Valor de Incertidumbre estándar | H6: Unidades en | K6: Porcentaje de Impacto
A7: Repetibilidad de las mediciones | B7: =MIN(Calculos!T28:T30) -> 0 | C7: =H1 -> psi | D7: A | E7: Modelo | F7: Normal | G7: =B7/SQRT(4) -> 0 | H7: =C7 -> psi | I7: 1 | J7: =G7*I7 -> 0 | K7: =POWER(J7,2)/POWER($J$16,2) -> 0
A8: Calibración de Patrón K=2 | B8: =MIN(Calculos!V28:V30) -> 0.058 | C8: =C7 -> psi | D8: B | E8: Modelo | F8: Normal | G8: =B8/2 -> 0.029 | H8: =C8 -> psi | I8: 1 | J8: =G8*I8 -> 0.029 | K8: =POWER(J8,2)/POWER($J$16,2) -> 0.2010679
A9: Error calibracion patron | B9: =MIN(Calculos!Y28:Y30) -> 0.1 | C9: =C8 -> psi | D9: B | E9: Modelo | F9: Rectangular | G9: =B9/SQRT(3) -> 0.057735027 | H9: =C9 -> psi | I9: 1 | J9: =G9*I9 -> 0.057735027 | K9: =POWER(J9,2)/POWER($J$16,2) -> 0.79693975
A10: Resolución Instrumento | B10: =Calculos!J9 -> 0.01 | C10: =C9 -> psi | D10: B | E10: Modelo | F10: Rectangular | G10: =B10/SQRT(12) -> 0.0028867513 | H10: =C10 -> psi | I10: 1 | J10: =G10*I10 -> 0.0028867513 | K10: =POWER(J10,2)/POWER($J$16,2) -> 0.0019923494
A11: Histeresis | B11: =MIN(Calculos!AA28:AA30) -> 0 | C11: =C10 -> psi | D11: A | E11: Modelo | F11: Rectangular | G11: =B11/SQRT(12) -> 0 | H11: =C11 -> psi | I11: 1 | J11: =G11*I11 -> 0 | K11: =POWER(J11,2)/POWER($J$16,2) -> 0
H16: Incertidumbre Combinanda | J16: =SQRT(J7^2+J8^2+J9^2+J10^2+J11^2+J12^2+J13^2) -> 0.064673539 | K16: =SUM(K7:K15) -> 1
H17: Factor de cobertura ( r = 95,45 % ) | J17: 2
H18: Incertidumbre expandida | J18: =J16*J17 -> 0.12934708
J19: =J18 -> 0.12934708

Sheet AG-ADM-F10-00
A1: NOMBRE | B1: Cliente | C1: Domicilio | D1: Contacto | E1: Correo | F1: Tel | G1: Ext | H1: IMP Ó DIG | I1: REQUISITOS ESPECIALES
A2: ALFMEIER | B2: ALFMEIER FRIEDRICHS & RATH DE MEXICO SA DE CV | C2: Av. Kalos No.108 Parque Industrial Kalos Apodaca N.L CP.66603 | D2: Wesley Reyes | E2: wesley.reyes@afrna.com | F2: (81) 1247-5500 | G2: N/A | H2: DIGITAL | I2: FORMATO DE FECHA SIN DÍA, SOLO MES Y AÑO, EJ: ENE-203
A3: ARSTAR | B3: ARSTAR SA DE CV | C3: AV PROL ADOLFO LOPEZ MATEOS No 500 COL VILLA DE SAN MIGUEL GPE NL | D3: NEFTALI GARCIA/ROBERTO RUBIO | E3: calidad.arstar@arstarinc.com /mejora.continua@arstarinc.com | F3: 8114311770 | G3: N/A | H3: IMPRESO | I3: N/A
A4: ASSYMEX | B4: ASSYMEX MONTERREY SA DE CV | C4: SAN SEBASTIAN 110, LOS LERMAS, GUADALUPE, NUEVO LEÓN | D4: ANA GÓMEZ | E4: mx.compras@assymexmty.com | F4: 81827856 | G4: N/A | H4: DIGITAL | I4: N/A
A5: BESSER | B5: BESSER ENERGY SAPI DE CV | C5: CALLE DE LA INDUSTRIA 215, PARQUE MARFER, SANTA CATARINA, NUEVO LEÓN | D5: DANIEL TORRES | E5: SLUJAN@BESSERLIGHTING.COM | F5: 8119711086 | G5: 1025 | H5: DIGITAL | I5: N/A
A6: BONADA | B6: SERVICIOS AERONAUTICOS SAB S.A DE C.V | C6: PALMERAS 546, PASEO DE LAS PALMAS, APODACA, NUEVO LEÓN | D6: ING. AMELIA ARREOLA | E6: ameliaarreola@hotmail.com | F6: 811720603 | G6: N/A
A7: BROMAKE | B7: BROMAKE SA DE CV | C7: Blvd. TLC 5063, Parque Industrial Milenium, Apodaca, Nuevo León, C.P. 66626 | D7: SAÚL LOZOYA | E7: qualitymty@bromake.com | F7: N/A | G7: N/A | H7: IMP Y DIG | I7: N/A
A8: BYSTROM MANUFACTURING | B8: BYSTROM MANUFACTURING | C8: Av. Adolfo Lopez Mateos 221 - Int. 5, Parque Industrial Bosques del Sur, Col. La Victoria, Guadalupe, Nuevo León, C.P. 67140 | D8: Ing. Andrea Salazar/ Ing. Javier Niño | E8: andrea.salazar@bystrom.com.mx/ calidad.bystrom@gmail.com | F8: 8127557359 | G8: N/A | H8: DIGITAL | I8: N/A
A9: CARRIER | B9: CARRIER MEXICO, S.A. DE C.V. | C9: Ave. Finsa #3196, Parque Industrial FINSA, Santa Catarina, Nuevo León, C.P. 66350 | D9: Ing. Eleaser Vazquez | E9: eleaser.vazquez@carrier.com | F9: 52 (81) 8124 7600 | G9: 5593 | H9: DIGITAL | I9: N/A
A10: CARRIER T | B10: CARRIER MEXICO | C10: Ave Alborada 541 Col. Finsa, Parque Industrial FINSA Guadalupe N.L. CP. 67132 | D10: J. Santos Valenciano Requenes | E10: jsantos.valenciano@carrier.com | F10: 8115629273 | G10: N/A
A11: CELESTICA ESTANDAR | B11: CELESTICA DE MONTERREY | C11: Calle 8va, Parque Industrial Monterrey 102, 66600 Cd Apodaca, N.L | D11: Guillermo Peña | E11: lurodri@celestica.com | F11: 81 8156 1500 | G11: 5939 | H11: DIGITAL | I11: Agregar nota: El equipo ha sido calibrado y aprobado apto para su uso/ No apto para su uso.
A12: CELESTICA MEDICO | B12: CELESTICA DE MONTERREY | C12: Calle 8va, Parque Industrial Monterrey 102, 66600 Cd Apodaca, N.L | D12: Nancy Montero | E12: nmonteroo@celestica.com | F12: 81 8156 1500 | G12: 5939 | H12: DIGITAL | I12: Agregar nota: El equipo ha sido calibrado y aprobado apto para su uso/ No apto para su uso. Revisar Schedule que envía el cliente.
A13: ENCORE | B13: ENCORE SYSTEMS SA DE CV | C13: Orion #1463, Interior 1-C, N/A Apodaca, Nuevo Leòn C.P.66600 | D13: KEVIN MORENO | E13: kmoreno@k-and-s.com pochoa@k-and-s.com | F13: (81) 8190-2505 | G13: N/A | H13: DIGITAL | I13: N/A
A14: EDWARDS | B14: AIM_SERVICIOS ADMINISTRATIVOS S. DE RL. DE C.V. | C14: CARRETERA A HUINALA KM. 2.8 PARQUE IND. LAS AMERICAS EDIF. B APODACA, NL 66640 MX | D14: Rogelio Ramos Villarreal | E14: Rogelio.ramos@edwardsvacuum.com | F14: 8131458615 | G14: N/A | H14: DIGITAL | I14: N/A
A15: ESAB | B15: ESAB MEXICO SA DE CV | C15: Diego Díaz de Berlanga, C.P. 66480, San Nicolás de los Garza, Nuevo León, Mexico | D15: JOSE ROMAN HERRERA | E15: jroman@esabmexico.com.mx | F15: 81 83053734 | G15: N/A | I15: N/A
A16: EVCO PLASTICS | B16: EVCO PLASTICS DE MEXICO S DE RL DE CV | C16: AV PABLO LIVAS # 4211 GUADALUPE VICTORIA, GUADALUPE, N. L. C.P. 67180 | D16: JOSÉ HERNÁNDEZ | E16: jose_h@evcoplastics.com.mx | F16: 83934455 | G16: 213 | H16: DIGITAL | I16: N/A
A17: FRANKLIN GPE PLANTA 1 | B17: FRANKLIN ELECTRIC | C17: Avenida De los Lagos #1085 Parque Industrial Acueducto, C.P. 67193 Ciudad Guadalupe, Nuevo Leon, Mexico. | D17: BELLANIRA AVALOS | E17: Bellanira.Avalos@fele.com | F17: 81 83800039 | G17: N/A | H17: DIGITAL | I17: N/A
A18: FRANKLIN GPE PLANTA 2 | B18: FRANKLIN ELECTRIC | C18: Avenida De los Lagos #1085 Parque Industrial Acueducto, C.P. 67193 Ciudad Guadalupe, Nuevo Leon, Mexico. | D18: EDGAR ARMIJO | E18: Edgar.Armijo@fele.com | F18: 81 83800040 | G18: N/A | H18: DIGITAL | I18: N/A
A19: FRANKLIN LINARES | B19: Motores Eléctricos Sumergibles de México S de RL de C.V | C19: Av. Industria Alimentaria # 2001 Parque Industrial Linares Linares Nuevo León México CP. 67735 | D19: ROLANDO TREVIÑO | E19: RTrevino@fele.com | F19: 8212140300 | G19: N/A | H19: DIGITAL | I19: N/A
A20: GEMINI | B20: Gemini Plastics de Mexico | C20: Carretera Saltillo Zacatecas km 4.5 sn, Nave 39, 40 y 41 | Saltillo, Coahuila, Mexico C.P. | 25315 | D20: Ing. Raul Rodriguez | E20: RAlejandroCerdaRodriguez@geminigroup.net | F20: 8444010025 | G20: N/A | H20: DIGITAL | I20: N/A
A21: GHSP | B21: GHSP MEXICO SA DE CV | C21: ARCO VIAL COL MORELOS 6261, SALTILLO, COAHUILA | D21: A quien corresponda | E21: ramirezj@ghsp.com | F21: 8441715352 | G21: N/A | H21: DIGITAL | I21: N/A
A22: GRUPO GONDI | B22: PAPEL Y EMPAQUES GONDI MONTERREY | C22: AUTOPISTA AL AEROPUERTO #1111 COL. NEXXUS GUADALUPE N.L. | D22: JAVIER SAUCEDA | E22: javier.sauceda@grupogondi.com | F22: 8188514300 | G22: N/A | H22: IMP Y DIG | I22: N/A
A23: H SAM | B23: HWASEUNG AUTOMOTIVE MEXICO S DE RL DE CV | C23: AV. INDUSTRIA 101 PARQUE INDUSTRIAL VYMNSA, SECTOR II C.P. 25904, RAMOS ARIZPE, COAHUILA | D23: ERICK M CERVANTES | E23: ecervantes@hsam.mx | F23: 8443090100 | G23: N/A | H23: DIGITAL | I23: N/A
A24: IMMI | B24: IMMI de México Production S de RL de CV | C24: Blvd. Cesar H. Cantu No. 176, Parque Industrial Alianza, Derramadero, Saltillo, Coahuila, México C.P. 25300 | D24: Ing. Antonio Guerrero | E24: aguerrero@imminet.com | F24: 844 454 8900 | G24: N/A | H24: DIGITAL | I24: N/A
A25: INICS | B25: INICS MEXICO SA DE CV | C25: AV.INDUSTRIAL 201, PARQUE INDUSTRIAL LA SILLA, APODACA, N.L. | D25: ALEJANDRO GARCÍA SALDAÑA | E25: alejandro@inics-america.com | F25: 8110898143 | G25: 110 | H25: DIGITAL | I25: N/A
A26: INSCAL&SERVICES | B26: Instruments Calibration & Services (InsCal & Services) | C26: Paseo de la Cañada #158, Col. Las Fuentes Colonial Reynosa, Tamaulipas C.P. 88703 | D26: A quien corresponda | E26: eorduna@inscalservices.com | F26: 899 445 3504 | G26: N/A | H26: DIGITAL | I26: N/A
A27: IPHARMA | B27: IPHARMA, S.A. DE C.V. | C27: CELAYA 322 COL. MITRAS CENTRO, Monterrey, N.L. México CP 64460 | D27: A quien corresponda | E27: marco.flores@i-pharma.com.mx | F27: 81 83 48 78 43 | G27: N/A | H27: DIGITAL | I27: FORMATO DE FECHA MM/DD/AAAA, todo con número, ejemplo (04/11/2023)
A28: JMH | B28: Diseños Metálicos JMH | C28: PRIVADA REGIOPARQUE, 111, REGIOPARQUE INDUSTRIAL, APODACA NUEVO LEON, 66600 | D28: ALBERTO MACIAS | E28: ADMINISTRACION@JMH.COM.MX | F28: 8180731160 | G28: N/A | H28: DIGITAL | I28: N/A
A29: JU YOUNG | B29: JU YOUNG SERVICES, SA DE CV | C29: BLVD. CARLOS SALINAS DE GORTARI #1000, COL. EL MILAGRO, APODACA, NUEVO LEÓN. | D29: CAROLAYY MUÑOZ/ARTURO GARCÍA | E29: arturo.garcia@juyoung.com//carolayy.espinoza@juyoung.com | F29: 8182202340 | G29: N/A | H29: DIGITAL | I29: N/A
A30: K + S SERVICES | B30: K&S SERVICIOS INDUSTRIALES, S.A. DE C.V. | C30: Calle: ORION 1463 Int.1 Colonia: sin colonia C.P. 66600 Apodaca, N.L. | D30: Ing. Patricio Ochoa | E30: nhernandez@k-and-s.com y pochoa@k-and-s.com | F30: 81 8190 2505 | G30: N/A | H30: DIGITAL | I30: N/A
A31: KATCON | B31: Katcon Mexico S.A. de C.V. | C31: Av Manuel Ordoñez #601, Sin Nombre de Col 3, 66350 Santa Catarina, N.L. | D31: Ing.Martin Meza | E31: martin.meza@katcon.com | F31: 81-8172-8530 | G31: N/A | H31: IMP Y DIG | I31: N/A
A32: KE ELEKTRONIK | B32: CEMM MEX S.A. DE C.V. / KE ELEKTRONIK | C32: IRIS, No. Ext. 105, 29 DE JULIO, C.P. 67205, GUADALUPE, NUEVO LEÓN, MEXICO | D32: CESAR SANCHEZ | E32: Cesar.Sanchez@ke-elektronik.de | F32: 812594 1236 | G32: N/A | H32: DIGITAL | I32: Como minimo una serie de 8 puntos de resultados en calibración.
A33: MAQPLASTICS | B33: MAQ PLASTICS SA DE CV | C33: JOSE DOMINGUEZ 1087, COL. NIÑO ARTILLERO, MONTERREY, NUEVO LEÓN, C.P. 64280 | D33: OSCAR NAVARRO | E33: maqplastics@gmail.com | F33: 8189895588 | G33: N/A | H33: DIGITAL | I33: N/A
A34: MARSTO | B34: Marsto Precision Instruments de Mexico, S de R L de CV | C34: Carretera a Agua Fría Libre Estatal No. 499 Edificio AF2 Prologis Park Agua Fría, Apodaca, N.L. México C.P. 66620 | D34: Cesar J. Quiroga Arizpe | E34: cesar.quiroga@marsto.com.mx | F34: 81 1089 4020 | G34: N/A | H34: IMP Y DIG | I34: N/A
A35: MEDSOLUTIONS | B35: Medsolutions S.A. de C.V. | C35: N/A | D35: Alejandro Mendoza Klein | E35: alejandro.mendoza@medsolutions.com.mx | F35: 4921464330 | G35: N/A | H35: DIGITAL | I35: N/A
A36: MELTER FP | B36: MELTER SA DE CV (DIV. FABRICACIONES PESADAS) | C36: Av. Luis Donaldo Colosio #402, Col. Comunidad ExHacienda San Francisco, Apodaca, Nuevo León, C.P. 66600 | D36: Ing. Raymundo Verastegui | E36: rverastegui@melter.com.mx | F36: 81 8000 96000 | G36: N/A | H36: DIGITAL | I36: N/A
A37: MELTER IC | B37: MELTER,S.A. DE C.V. | C37: CALLE SPECTRUM 233, PARQUE INDUSTRIAL FINSA, C.P. 66600, MEXICO | D37: Manuel Vázquez | E37: mvazquez@melter.com.mx | F37: 818000-9600 | G37: N/A | H37: IMP Y DIG | I37: LA VIGENCIA EN EL CERTIFICADO DEBE LLEVAR LA LEYENDA "Vigencia definidia por el usuario" y en la etiqueta el siguiente formato **/**/****
A38: METRIC WORKS | B38: Metrics Works Saltillo | C38: Av. Industria Automotriz 6040-C Parque Industrial Ramos Arizpe | D38: Carlos Rosales | E38: jperalez@metricsworks.com | F38: 844 159 5116 | G38: N/A | H38: IMP Y DIG | I38: N/A
A39: MYTAAC | B39: MANUFACTURAS Y TECNOLOGIAS AVANZADAS DE ACERO SA DE CV | C39: ANTONIO E MARCOS 1219, COMOPOLIS, APODACA, NUEVO LEÓN, C.P. 66612 | D39: Ing Ronerto Segura | E39: robertosc@mytaac.com | F39: (81) 1958 9390 | G39: N/A | H39: DIGITAL | I39: N/A
A40: NAS | B40: NAS MEXICO SA DE CV | C40: RIVADA ANDRES GUAJARDO #360 APODACA | D40: ING RENE MARTINEZ | E40: rm4534@northamericanstainless.com | F40: 81 1253 7700 | G40: N/A | H40: DIGITAL | I40: N/A
...

Sheet BD_Clientes
A1: Nombre | B1: Domicilio | C1: Contacto | D1: Correo | E1: Telefono
A2: International ASSEMBLY | B2: Emilio Carranza #2421 Col. Jardines de Tolteca C.P. 67178 Guadalupe, N.L. MX | C2: Joel Martínez | D2: joel@internationalassembly.com | E2: (81) 8479-4080 | F2: N/A | G2: DIGITAL
A3: KATCON MÉXICO S.A. DE C.V. | B3: AV. MANUEL ORDOÑEZ #601, SIN NOMBRE DE COL 3, SANTA CATARINA, NUEVO LEÓN, C.P. 66350 | C3: ING MARTIN MEZA | D3: MARTIN.MEZA@KATCON.COM | E3: (81) 8172 8530 | F3: N/A | G3: DIGITAL
A4: GHSP MEXICO SA DE CV | B4: ARCO VIAL COL MORELOS 6261, SALTILLO, COAHUILA | C4: A QUIEN CORRESPONDA | D4: RAMIREZJ@GHSP.COM | E4: (84) 4171 5352 | F4: N/A | G4: DIGITAL
A5: SANILTECH SA DE CV | B5: CARR. NUEVO LAREDO KM 16.5 INT. 1-B, COL. MOISÉS SÁENZ, APODACA, NUEVO LEÓN, MÉXICO, C.P..66613 | C5: ING. JOSE MORALES CASTILLO | D5: JOSE.MORALES@COAVIS.COM | E5: (81) 8385 0176 | F5: N/A | G5: DIGITAL
A6: PROVEEDORA FARMACEUTICA RASE S.A DE C.V | B6: SAN BERNABE #205, COLONIA VALLE MORELOS, MONTERREY, NUEVO LEON | C6: DANIEL MACÍAS | D6: COMPRAS.OPERATIVAS@RASE.COM.MX | E6: (81) 2679 3089 | F6: N/A | G6: DIGITAL
A7: MEDSOLUTIONS S.A. DE C.V. | B7: N/A | C7: ALEJANDRO MENDOZA KLEIN | D7: ALEJANDRO.MENDOZA@MEDSOLUTIONS.COM.MX | E7: (49) 2146 4330 | F7: N/A | G7: DIGITAL
A8: JU YOUNG SERVICES, SA DE CV | B8: BLVD. CARLOS SALINAS DE GORTARI #1000, COL. EL MILAGRO, APODACA, NUEVO LEÓN. | C8: CAROLAYY MUÑOZ/ARTURO GARCÍA | D8: ARTURO.GARCIA@JUYOUNG.COM | E8: 8182202340 | F8: N/A | G8: DIGITAL | H8: Correo: CAROLAYY.ESPINOZA@JUYOUNG.COM Hay dos correos.
A9: MAXON LIFT | B9: BLVD INSTRIAL NEXXUS 1711, SALINAS VICTORIA, NUEVO LEÓN | C9: Fernanda Garcia | D9: fergarcia@femsafab.com | E9: 8110664201 | F9: N/A | G9: DIGITAL
A10: INDUSTRIAS ELECTRONICAS PACIFICO SA DE CV PLANTA 4 | B10: NEUTRON 110, PARQUE INDUSTRIAL STIVA, APODACA, NUEVO LEÓN, C.P. 66600 | C10: JOSE ALEJO PÉREZ NAVARRO | D10: JOSEALEJO.PEREZ@SE.COM | E10: (81) 1545 7298 | F10: N/A | G10: DIGITAL
A11: MANUFACTURAS Y TECNOLOGIAS AVANZADAS DE ACERO SA DE CV | B11: ANTONIO E MARCOS 1219, COMOPOLIS, APODACA, NUEVO LEÓN, C.P. 66612 | C11: ING. ROBERTO SEGURA | D11: ROBERTOSC@MYTAAC.COM | E11: (81) 1958 9390 | F11: N/A | G11: DIGITAL
A12: RUHRPUMPEN SA DE CV | B12: CIUDAD INDUSTRIAL MITRAS, NIQUEL 9204 INT C, GARCIA, NUEVO LEÓN, MÉXICO, C.P. 66000 | C12: SERGIO LARA GARCIA | D12: SLARA@RUHRPUMPEN.COM | E12: (81) 8158 5548 | F12: N/A | G12: DIGITAL
A13: OEM SUPPLY | B13: AV. CENTRAL 5485, COL. LAS HUERTAS, GUADALUPE, NUEVO LEÓN | C13: A QUIEN CORRESPONDA | D13: ACOMPRAS@OEMSUPPLY.MX | E13: (81) 2051 5987 | F13: N/A | G13: DIGITAL
A14: MANITOWOC FSG MANUFACTURA MÉXICO S DE RL DE CV | B14: VÍA A TAMPICO #1601 PARQUE INDUSTRIAL FINSA GUADALUPE, C.P. 67132 | C14: ING. ROBERTO LÓPEZ MEDELLÍN | D14: ROBERTO.LOPEZMEDELLIN@PENTAIR.COM | E14: (81) 1211 2191 | F14: N/A | G14: DIGITAL
A15: PHILLIPS CONNECT | B15: AV. BOB PHILLIPS # 755, COL. EL LLANO, ARTEGA COAHUILA, C.P. 25350 | C15: ALEJANDRO CHÁVEZ | D15: FACHAVEZ@PHILLIPSIND.COM | E15: (65) 6144 4138 | F15: N/A | G15: DIGITAL
A16: CELESTICA DE MONTERREY (EDIFICIO L) | B16: Eje Metropolitano 910 526, SFO, 66076 Cdad. Gral. Escobedo, N.L. | C16: GUILLERMO PEÑA | D16: LURODRI@CELESTICA.COM | E16: (81) 8156 1502 | F16: N/A | G16: DIGITAL | H16: AGREGAR NOTA: "El equipo ha sido calibrado y es apto para su uso" ó "El equipo ha sido calibrado y no es apto para su uso", según corresponda
A17: NYX MEXICO PLASTICS | B17: CARRETERA LOMA ALTA #999, FRACC. LAS CASAS, ARTEAGA, COAHUILA MEXICO, C.P. 25354 | C17: PEDRO PABLO PEREZ PRADO | D17: PEDRO.PEREZ@NYXINC.COM | E17: (84) 4444 0211 | F17: N/A | G17: DIGITAL
A18: TENMFG DE MÉXICO S DE RL DE CV | B18: CALLE ENCINOS #101 COL. LOS PUERTOS JUÁREZ NUEVO LEÓN, C.P. 67252 | C18: ING. FRANCISCO AGUILAR | D18: FRANCISCO.AGULAR@CADREX.COM | E18: (81) 2034 0655 | F18: N/A | G18: DIGITAL
A19: PRODUCTOS ARPAPEL SA DE CV | B19: AV. DEL PARQUE 2010, AIRPORT TECHNOLOGY PARK, PESQUERÍA, NUEVO LEÓN MÉXICO, C.P. 66657 | C19: FERNANDO ENRIQUE SANCHEZ CARRIZALEZ | E19: (55) 2122 3860 | F19: N/A | G19: DIGITAL
A20: AIM_SERVICIOS ADMINISTRATIVOS S. DE RL. DE C.V. | B20: CARRETERA A HUINALA KM. 2.8 PARQUE IND. LAS AMERICAS EDIF. B APODACA, NUEVO LEÓN, C.P. 66640 MX | C20: ROGELIO RAMOS VILLAREAL | D20: ROGELIO.RAMOS@EDWARDSVACUUM.COM | E20: (81) 3145 8615 | F20: N/A | G20: DIGITAL | H20: Vigencia SOLO MES Y AÑO, datos de equipos, puntos de calibración y tolerancia para dictamen proporcionada por CLIENTE.
A21: SERVICIOS INDUSTRIALES MACHS S.A. DE C.V. | B21: ROMULO DIAZ DE LA VEGA 1812 | C21: CALIDAD | D21: CALIDAD2@MACHS.COM.MX | E21: (81) 8351 5108 | F21: N/A | G21: DIGITAL
A22: MARTINREA INTERNACIONAL DE MEXICO, SA DE CV | B22: INDUSTRIA DE LA TRANSFORMACIÓN #3131, PARQUE INDUSTRIAL RAMOS ARIZPE, RAMOS ARIZPE, MÉXICO, C.P. 259 | C22: HECTOR HERNANDEZ | D22: HECTOR.HERNANDEZ@MARTINREA.COM | E22: (84) 4866 1066 | F22: N/A | G22: DIGITAL
A23: CARRIER MÉXICO (PLANTA T) | B23: AVE ALBORADA 541 COL. FINSA, PARQUE INDUSTRIAL FINSA GUADALUPE, NUEVO LEÓN, CP. 67132 | C23: J. SANTOS VALENCIANO REQUENES | D23: JSANTOS.VALENCIANO@CARRIER.COM | E23: (81) 1562 9273 | F23: N/A | G23: DIGITAL | H23: CERTIFICADOS IMPRESOS
A24: KRONOS DECANTER SERVICES | B24: DEL ACERO 113, PARQUE INDUSTRIAL ESCOBEDO, 66062 CDAD. GRAL. ESCOBEDO, NUEVO LEÓN | C24: SARAI CONTRERAS | D24: COMPRAS@KRONOSDECANTER.COM | E24: (81) 8148 8694 | F24: N/A | G24: DIGITAL
A25: METRICS MEXICO TRADING COMPANY | B25: MARGARITO GARZA GONZALEZ #300 EL SABINAL, APODACA, NUEVO LEÓN | C25: ING. IVAN IBARRA | D25: JPERALEZ@METRICSWORKS.COM | E25: (81) 2040 7613 | F25: N/A | G25: DIGITAL
A26: SUPERIOR SPINDLE SERVICE MEXICO | B26: ORION 1463, COL. PARQUE. IND. ORION, C.P. 66600 APODACA, NUEVO LEON, MEXICO | C26: N/A | D26: EPALACIOS@K-AND-S.COM | E26: (81) 8190-2505 | F26: N/A | G26: DIGITAL
A27: MELTER S.A. DE C.V. | B27: CALLE SPECTRUM 233, PARQUE INDUSTRIAL FINSA, C.P. 66600, MEXICO | C27: MANUEL VÁZQUEZ | D27: MVAZQUEZ@MELTER.COM.MX | E27: (81) 8000 9600 | F27: N/A | G27: DIGITAL
A28: STEEL TECHNOLOGIES DE MÉXICO | B28: AV. AMALFI #124, PARQUE INDUSTRIAL PROPARK PESQUERÍA, NUEVO LEÓN | C28: ING. ROBERTO QUINTANILLA PUENTE | D28: RQUINTANILLA@STEELTECHNOLOGIES.COM.MX | E28: (81) 8196 4700 | F28: N/A | G28: DIGITAL
A29: TN MANUFACTURING | B29: AV. REGIO PARQUE 157, REGIO PARQUE INDUSTRIAL, APODACA, NUEVO LEÓN | C29: ESAÚ DE LEÓN | D29: CALIDAD@TNMANUFACTURING.COM | E29: (81) 1334 0396 | F29: N/A | G29: DIGITAL
A30: FRANKLIN ELECTRIC (GPE PLANTA 2) | B30: AVENIDA DE LOS LAGOS #1085,PARQUE INDUSTRIAL ACUEDUCTO, CIUDAD GUADALUPE, NUEVO LEÓN, MEXICO | C30: EDGAR ARMIJO | D30: EDGAR.ARMIJO@FELE.COM | E30: (81) 8380 0040 | F30: N/A | G30: DIGITAL
A31: NEUROCYTONIX MEXICO SA DE CV | B31: CALZADA SAN PEDRO 503, COL. FUENTES DEL VALLE, SAN PEDRO GARZA GARCÍA, NUEVO LEÓN, C.P. 66224 | C31: BRAYAN ABELARDO SILVA HERRERA | D31: BSilva@NEUROCYTONIX.COM | E31: (81) 3552 7403 | F31: N/A | G31: DIGITAL | H31: Fecha SIN día, solo MES Y AÑO (Ej. 2025-DIC 2026-DIC) , es a 6 meses
A32: STARION EV MEXICO | B32: AVE. LA CONCORDIA #6095, PARQUE INDUSTRIAL EL SABINAL, APODACA, NUEVO LEÓN, C.P. 66648 | C32: RICARDO JARAMILLO | D32: RICARDO.A@STARION.CO.KR | E32: (81) 1648 5368 | F32: N/A | G32: DIGITAL
A33: MAQUINARIA DOGA SA DE CV | B33: PUERTO VALLARTA 684, LA FE, ALFONSO ACEVEDO | C33: ALFONSO ACEVEDO | D33: PROYECTOS.DOGA21@GMAIL.COM | E33: (81) 8144 1100 | F33: N/A | G33: DIGITAL
A34: ACCEL LOGISTICA | B34: AV. LERDO DE TEJADA 777, COL. TABACHINES, SAN NICOLÁS DE LOS GARZA | C34: N/A | D34: NA@NA | E34: N/A | F34: N/A | G34: DIGITAL
A35: STUCKI DE MÉXICO | B35: DE LOS ANDES 200, COYOACÁN, MONTERREY, NUEVO LEÓN, C.P. 64510 | C35: BENJAMIN RODRIGUEZ | D35: BENJAMIN.RODRIGUEZ@STUCKI.MX | E35: (81) 1127 2896 | F35: N/A | G35: DIGITAL
A36: EQUIPO AUTOMOTRIZ AMERICANA S.A. DE C.V. (JOYSON) | B36: Carretera a Santa Rosa km 3.5 Apodaca, N.L. | C36: Ing. Manuel Sustaita | D36: Manuel.Sustaita@joysonsafety.com | E36: (81) 8018 4875 | F36: N/A | G36: DIGITAL
A37: MAQUINADOS INDUSTRIALES TAMEZ SA DE CV | B37: BOSTON, 410, FRACCIONAMIENTO KENNEDY, MONTERREY, NUEVO LEÓN, C.P. 64260 | C37: NICOLAS PACHECO | D37: CALIDAD@MITSACNC.COM | E37: (81) 8376 5628 | F37: N/A | G37: DIGITAL
A38: NAS MEXICO SA DE CV | B38: PRIVADA ANDRES GUAJARDO #360 APODACA | C38: ING JOSE GARCIA | D38: JG5443@NORTHAMERICANSTAINLESS.COM | E38: (81) 1253 7700 | F38: N/A | G38: DIGITAL
A39: JOHNSON CONTROLS PLANTA 2 | B39: BLVD TLC #30 | C39: EMMANUEL RUIZ OYERVIDES | D39: EMMANUEL.RUIZ.OYERVIDES@JCI.COM | E39: (81) 1822 8828 | F39: N/A | G39: DIGITAL
A40: GEMINI PLASTICS DE MEXICO | B40: CARRETERA SALTILLO ZACATECAS KM 4.5 SN, NAVE 39, 40 Y 41, SALTILLO, COAHUILA, MÉXICO, C.P. 25315 | C40: ING. RAUL RODRIGUEZ | D40: RALEJANDROCERDARODRIGUEZ@GEMINIGROUP.NET | E40: (84) 4401 0025 | F40: N/A | G40: DIGITAL
...
